{"name": "test_query_cannot_be_run[Create query (not SELECT)]", "status": "passed", "description": "\n        As a user\n        When I run query with incorrect data\n        Then I get an error response\n        ", "attachments": [{"name": "log", "source": "299b29c2-1025-45e8-b737-71c37c3c4fd5-attachment.txt", "type": "text/plain"}, {"name": "stdout", "source": "6f87695a-3e39-4812-8d39-5af1286735a5-attachment.txt", "type": "text/plain"}], "parameters": [{"name": "query_data", "value": "QueryData(query='CREATE TABLE Abc (ID int)')"}, {"name": "expected_error", "value": "<harness.api.model.error.api_error.ApiError object at 0x10f41c1c0>"}], "start": 1698654813483, "stop": 1698654813520, "uuid": "aab2acb8-39ec-4e2b-9be7-ef3459bdd931", "historyId": "e50966c32876108dcb89e02cf4da2a39", "testCaseId": "4b2dc8dbeda1194c185f4356f562de89", "fullName": "tests.integration.api.consume.powerbi.test_run_query.TestApiRunQuery#test_query_cannot_be_run", "labels": [{"name": "story", "value": "Query cannot be run"}, {"name": "feature", "value": "Run query"}, {"name": "parentSuite", "value": "[API] ConsumeQuery"}, {"name": "tag", "value": "@pytest.mark.usefixtures('authenticate_neos_admin')"}, {"name": "tag", "value": "negative"}, {"name": "tag", "value": "consume"}, {"name": "suite", "value": "test_run_query"}, {"name": "subSuite", "value": "TestApiRunQuery"}, {"name": "host", "value": "Is-MacBook-Pro.local"}, {"name": "thread", "value": "26202-MainThread"}, {"name": "framework", "value": "pytest"}, {"name": "language", "value": "cpython3"}, {"name": "package", "value": "tests.integration.api.consume.powerbi.test_run_query"}]}