{"name": "test_query_cannot_be_run[Not supported engine]", "status": "passed", "description": "\n        As a user\n        When I run query with incorrect data\n        Then I get an error response\n        ", "attachments": [{"name": "log", "source": "f29e3b31-6e31-4f1a-849f-da2b8711209b-attachment.txt", "type": "text/plain"}, {"name": "stdout", "source": "6a88f56f-5259-4167-b112-5c35c7143632-attachment.txt", "type": "text/plain"}], "parameters": [{"name": "query_data", "value": "QueryData(query='SELECT * FROM test.neos.test_table')"}, {"name": "expected_error", "value": "<harness.api.model.error.api_error.ApiError object at 0x10f41c3a0>"}], "start": 1698654813923, "stop": 1698654813958, "uuid": "3ecfe132-061f-4257-b3e1-156b0d894d6e", "historyId": "a210eee697fc724e9fcfb5cca4f7fdda", "testCaseId": "4b2dc8dbeda1194c185f4356f562de89", "fullName": "tests.integration.api.consume.powerbi.test_run_query.TestApiRunQuery#test_query_cannot_be_run", "labels": [{"name": "story", "value": "Query cannot be run"}, {"name": "feature", "value": "Run query"}, {"name": "parentSuite", "value": "[API] ConsumeQuery"}, {"name": "tag", "value": "@pytest.mark.usefixtures('authenticate_neos_admin')"}, {"name": "tag", "value": "negative"}, {"name": "tag", "value": "consume"}, {"name": "suite", "value": "test_run_query"}, {"name": "subSuite", "value": "TestApiRunQuery"}, {"name": "host", "value": "Is-MacBook-Pro.local"}, {"name": "thread", "value": "26202-MainThread"}, {"name": "framework", "value": "pytest"}, {"name": "language", "value": "cpython3"}, {"name": "package", "value": "tests.integration.api.consume.powerbi.test_run_query"}]}