{"name": "test_query_cannot_be_run[Incorrect table name]", "status": "passed", "description": "\n        As a user\n        When I run query with incorrect data\n        Then I get an error response\n        ", "attachments": [{"name": "log", "source": "468881c9-6516-4240-88b7-7a995cb58a18-attachment.txt", "type": "text/plain"}, {"name": "stdout", "source": "27e2d28e-d36b-4f37-bcb1-7e7eef76be0c-attachment.txt", "type": "text/plain"}], "parameters": [{"name": "query_data", "value": "QueryData(query='SELECT * FROM incorrect_table')"}, {"name": "expected_error", "value": "<harness.api.model.error.api_error.ApiError object at 0x10f41c310>"}], "start": 1698654813686, "stop": 1698654813723, "uuid": "6ea03692-7f22-42c5-a6fc-1ac272d92592", "historyId": "5e9075f01c86b7bcd3ad9bd1bba96122", "testCaseId": "4b2dc8dbeda1194c185f4356f562de89", "fullName": "tests.integration.api.consume.powerbi.test_run_query.TestApiRunQuery#test_query_cannot_be_run", "labels": [{"name": "story", "value": "Query cannot be run"}, {"name": "feature", "value": "Run query"}, {"name": "parentSuite", "value": "[API] ConsumeQuery"}, {"name": "tag", "value": "@pytest.mark.usefixtures('authenticate_neos_admin')"}, {"name": "tag", "value": "negative"}, {"name": "tag", "value": "consume"}, {"name": "suite", "value": "test_run_query"}, {"name": "subSuite", "value": "TestApiRunQuery"}, {"name": "host", "value": "Is-MacBook-Pro.local"}, {"name": "thread", "value": "26202-MainThread"}, {"name": "framework", "value": "pytest"}, {"name": "language", "value": "cpython3"}, {"name": "package", "value": "tests.integration.api.consume.powerbi.test_run_query"}]}